[ 2023-08-25 16:41:19,885 ] 224 werkzeug - INFO - [31m[1mWARNING: This is a development server. Do not use it in a production deployment. Use a production WSGI server instead.[0m
 * Running on all addresses (0.0.0.0)
 * Running on http://127.0.0.1:5000
 * Running on http://192.168.0.102:5000
[ 2023-08-25 16:41:19,885 ] 224 werkzeug - INFO - [33mPress CTRL+C to quit[0m
[ 2023-08-25 16:43:42,786 ] 224 werkzeug - INFO - 127.0.0.1 - - [25/Aug/2023 16:43:42] "GET / HTTP/1.1" 200 -
[ 2023-08-25 16:43:44,214 ] 224 werkzeug - INFO - 127.0.0.1 - - [25/Aug/2023 16:43:44] "[33mGET /favicon.ico HTTP/1.1[0m" 404 -
[ 2023-08-25 16:50:19,312 ] 224 werkzeug - INFO - 127.0.0.1 - - [25/Aug/2023 16:50:19] "GET /predictdata HTTP/1.1" 200 -
[ 2023-08-25 16:50:52,817 ] 1744 app - ERROR - Exception on /predictdata [POST]
Traceback (most recent call last):
  File "c:\Users\Admin\Documents\DS_Python\# VC_IMP\Personal Data\projects\5. Krish_end_to_end_series1\src\pipeline\predict_pipeline.py", line 44, in get_data_as_data_frame
    "race_ethnicity":[self.race_ethnicity],
AttributeError: 'CustomData' object has no attribute 'race_ethnicity'

During handling of the above exception, another exception occurred:

Traceback (most recent call last):
  File "C:\ProgramData\Anaconda3\envs\myenv\lib\site-packages\flask\app.py", line 2528, in wsgi_app
    response = self.full_dispatch_request()
  File "C:\ProgramData\Anaconda3\envs\myenv\lib\site-packages\flask\app.py", line 1825, in full_dispatch_request
    rv = self.handle_user_exception(e)
  File "C:\ProgramData\Anaconda3\envs\myenv\lib\site-packages\flask\app.py", line 1823, in full_dispatch_request
    rv = self.dispatch_request()
  File "C:\ProgramData\Anaconda3\envs\myenv\lib\site-packages\flask\app.py", line 1799, in dispatch_request
    return self.ensure_sync(self.view_functions[rule.endpoint])(**view_args)
  File "c:/Users/Admin/Documents/DS_Python/# VC_IMP/Personal Data/projects/5. Krish_end_to_end_series1/app.py", line 33, in predict_datapoint
    pred_df=data.get_data_as_data_frame()
  File "c:\Users\Admin\Documents\DS_Python\# VC_IMP\Personal Data\projects\5. Krish_end_to_end_series1\src\pipeline\predict_pipeline.py", line 55, in get_data_as_data_frame
    raise CustomException(e,sys)
src.exception.CustomException: Error occured in python script name [c:\Users\Admin\Documents\DS_Python\# VC_IMP\Personal Data\projects\5. Krish_end_to_end_series1\src\pipeline\predict_pipeline.py] line number [44] error message['CustomData' object has no attribute 'race_ethnicity']
[ 2023-08-25 16:50:52,821 ] 224 werkzeug - INFO - 127.0.0.1 - - [25/Aug/2023 16:50:52] "[35m[1mPOST /predictdata HTTP/1.1[0m" 500 -
[ 2023-08-25 16:51:23,161 ] 224 werkzeug - INFO - 127.0.0.1 - - [25/Aug/2023 16:51:23] "GET / HTTP/1.1" 200 -
[ 2023-08-25 16:52:01,619 ] 224 werkzeug - INFO - 127.0.0.1 - - [25/Aug/2023 16:52:01] "GET /predictdata HTTP/1.1" 200 -
[ 2023-08-25 16:52:39,215 ] 1744 app - ERROR - Exception on /predictdata [POST]
Traceback (most recent call last):
  File "c:\Users\Admin\Documents\DS_Python\# VC_IMP\Personal Data\projects\5. Krish_end_to_end_series1\src\pipeline\predict_pipeline.py", line 44, in get_data_as_data_frame
    "race_ethnicity":[self.race_ethnicity],
AttributeError: 'CustomData' object has no attribute 'race_ethnicity'

During handling of the above exception, another exception occurred:

Traceback (most recent call last):
  File "C:\ProgramData\Anaconda3\envs\myenv\lib\site-packages\flask\app.py", line 2528, in wsgi_app
    response = self.full_dispatch_request()
  File "C:\ProgramData\Anaconda3\envs\myenv\lib\site-packages\flask\app.py", line 1825, in full_dispatch_request
    rv = self.handle_user_exception(e)
  File "C:\ProgramData\Anaconda3\envs\myenv\lib\site-packages\flask\app.py", line 1823, in full_dispatch_request
    rv = self.dispatch_request()
  File "C:\ProgramData\Anaconda3\envs\myenv\lib\site-packages\flask\app.py", line 1799, in dispatch_request
    return self.ensure_sync(self.view_functions[rule.endpoint])(**view_args)
  File "c:/Users/Admin/Documents/DS_Python/# VC_IMP/Personal Data/projects/5. Krish_end_to_end_series1/app.py", line 33, in predict_datapoint
    pred_df=data.get_data_as_data_frame()
  File "c:\Users\Admin\Documents\DS_Python\# VC_IMP\Personal Data\projects\5. Krish_end_to_end_series1\src\pipeline\predict_pipeline.py", line 55, in get_data_as_data_frame
    raise CustomException(e,sys)
src.exception.CustomException: Error occured in python script name [c:\Users\Admin\Documents\DS_Python\# VC_IMP\Personal Data\projects\5. Krish_end_to_end_series1\src\pipeline\predict_pipeline.py] line number [44] error message['CustomData' object has no attribute 'race_ethnicity']
[ 2023-08-25 16:52:39,218 ] 224 werkzeug - INFO - 127.0.0.1 - - [25/Aug/2023 16:52:39] "[35m[1mPOST /predictdata HTTP/1.1[0m" 500 -
